<?xml version="1.0" encoding="UTF-8"?>
<!-- Generated by org.testng.reporters.JUnitReportReporter -->
<testsuite hostname="INBDQ2LT3XPCPV2" failures="1" tests="4" name="practice.RestAssuredTest" time="5.782" errors="0" timestamp="2022-02-06T02:46:28 IST" skipped="0">
  <testcase classname="practice.RestAssuredTest" name="post_practice" time="1.014"/>
  <system-out/>
  <testcase classname="practice.RestAssuredTest" name="self_practise" time="1.265">
    <failure message="expected:&lt;422&gt; but was:&lt;201&gt;" type="java.lang.AssertionError">
      <![CDATA[java.lang.AssertionError: expected:<422> but was:<201>
at org.junit.Assert.fail(Assert.java:93)
at org.junit.Assert.failNotEquals(Assert.java:647)
at org.junit.Assert.assertEquals(Assert.java:128)
at org.junit.Assert.assertEquals(Assert.java:472)
at org.junit.Assert.assertEquals(Assert.java:456)
at practice.RestAssuredTest.self_practise(RestAssuredTest.java:138)
at java.base/jdk.internal.reflect.NativeMethodAccessorImpl.invoke0(Native Method)
at java.base/jdk.internal.reflect.NativeMethodAccessorImpl.invoke(NativeMethodAccessorImpl.java:62)
at java.base/jdk.internal.reflect.DelegatingMethodAccessorImpl.invoke(DelegatingMethodAccessorImpl.java:43)
at java.base/java.lang.reflect.Method.invoke(Method.java:566)
at org.testng.internal.MethodInvocationHelper.invokeMethod(MethodInvocationHelper.java:133)
at org.testng.internal.TestInvoker.invokeMethod(TestInvoker.java:598)
at org.testng.internal.TestInvoker.invokeTestMethod(TestInvoker.java:173)
at org.testng.internal.MethodRunner.runInSequence(MethodRunner.java:46)
at org.testng.internal.TestInvoker$MethodInvocationAgent.invoke(TestInvoker.java:824)
at org.testng.internal.TestInvoker.invokeTestMethods(TestInvoker.java:146)
at org.testng.internal.TestMethodWorker.invokeTestMethods(TestMethodWorker.java:146)
at org.testng.internal.TestMethodWorker.run(TestMethodWorker.java:128)
at java.base/java.util.ArrayList.forEach(ArrayList.java:1541)
at org.testng.TestRunner.privateRun(TestRunner.java:794)
at org.testng.TestRunner.run(TestRunner.java:596)
at org.testng.SuiteRunner.runTest(SuiteRunner.java:377)
at org.testng.SuiteRunner.runSequentially(SuiteRunner.java:371)
at org.testng.SuiteRunner.privateRun(SuiteRunner.java:332)
at org.testng.SuiteRunner.run(SuiteRunner.java:276)
at org.testng.SuiteRunnerWorker.runSuite(SuiteRunnerWorker.java:53)
at org.testng.SuiteRunnerWorker.run(SuiteRunnerWorker.java:96)
at org.testng.TestNG.runSuitesSequentially(TestNG.java:1212)
at org.testng.TestNG.runSuitesLocally(TestNG.java:1134)
at org.testng.TestNG.runSuites(TestNG.java:1063)
at org.testng.TestNG.run(TestNG.java:1031)
at org.testng.remote.AbstractRemoteTestNG.run(AbstractRemoteTestNG.java:115)
at org.testng.remote.RemoteTestNG.initAndRun(RemoteTestNG.java:251)
at org.testng.remote.RemoteTestNG.main(RemoteTestNG.java:77)
]]>
    </failure>
  </testcase> <!-- self_practise -->
  <system-out/>
  <testcase classname="practice.RestAssuredTest" name="GetWeatherDetails" time="2.148"/>
  <system-out/>
  <testcase classname="practice.RestAssuredTest" name="query_parameter" time="1.355"/>
  <system-out/>
</testsuite> <!-- practice.RestAssuredTest -->
